[2023-07-19T14:59:41.069+0000] {taskinstance.py:1103} INFO - Dependencies all met for dep_context=non-requeueable deps ti=<TaskInstance: etl.extract_postgresql_data manual__2023-07-19T14:59:38.623731+00:00 [queued]>
[2023-07-19T14:59:41.089+0000] {taskinstance.py:1103} INFO - Dependencies all met for dep_context=requeueable deps ti=<TaskInstance: etl.extract_postgresql_data manual__2023-07-19T14:59:38.623731+00:00 [queued]>
[2023-07-19T14:59:41.089+0000] {taskinstance.py:1308} INFO - Starting attempt 1 of 2
[2023-07-19T14:59:41.130+0000] {taskinstance.py:1327} INFO - Executing <Task(PythonOperator): extract_postgresql_data> on 2023-07-19 14:59:38.623731+00:00
[2023-07-19T14:59:41.135+0000] {standard_task_runner.py:57} INFO - Started process 134 to run task
[2023-07-19T14:59:41.161+0000] {standard_task_runner.py:84} INFO - Running: ['***', 'tasks', 'run', 'etl', 'extract_postgresql_data', 'manual__2023-07-19T14:59:38.623731+00:00', '--job-id', '8', '--raw', '--subdir', 'DAGS_FOLDER/etl.py', '--cfg-path', '/tmp/tmpd8qkv7z_']
[2023-07-19T14:59:41.176+0000] {standard_task_runner.py:85} INFO - Job 8: Subtask extract_postgresql_data
[2023-07-19T14:59:41.319+0000] {task_command.py:410} INFO - Running <TaskInstance: etl.extract_postgresql_data manual__2023-07-19T14:59:38.623731+00:00 [running]> on host 6f676df8422e
[2023-07-19T14:59:41.447+0000] {taskinstance.py:1547} INFO - Exporting env vars: AIRFLOW_CTX_DAG_OWNER='Rodrigo Carvalho' AIRFLOW_CTX_DAG_ID='etl' AIRFLOW_CTX_TASK_ID='extract_postgresql_data' AIRFLOW_CTX_EXECUTION_DATE='2023-07-19T14:59:38.623731+00:00' AIRFLOW_CTX_TRY_NUMBER='1' AIRFLOW_CTX_DAG_RUN_ID='manual__2023-07-19T14:59:38.623731+00:00'
[2023-07-19T14:59:41.448+0000] {logging_mixin.py:150} INFO - An unexpected error has occured: invalid literal for int() with base 10: 'None'
[2023-07-19T14:59:41.449+0000] {taskinstance.py:1824} ERROR - Task failed with exception
Traceback (most recent call last):
  File "/home/airflow/.local/lib/python3.7/site-packages/airflow/operators/python.py", line 181, in execute
    return_value = self.execute_callable()
  File "/home/airflow/.local/lib/python3.7/site-packages/airflow/operators/python.py", line 198, in execute_callable
    return self.python_callable(*self.op_args, **self.op_kwargs)
  File "/opt/airflow/dags/etl.py", line 65, in extract_postgresql_data
    engine = create_engine_source_db()
  File "/opt/airflow/dags/etl.py", line 34, in create_engine_source_db
    f'postgresql://{user}:{password}@{host}:{port}/{database}'
  File "<string>", line 2, in create_engine
  File "/home/airflow/.local/lib/python3.7/site-packages/sqlalchemy/util/deprecations.py", line 375, in warned
    return fn(*args, **kwargs)
  File "/home/airflow/.local/lib/python3.7/site-packages/sqlalchemy/engine/create.py", line 514, in create_engine
    u = _url.make_url(url)
  File "/home/airflow/.local/lib/python3.7/site-packages/sqlalchemy/engine/url.py", line 738, in make_url
    return _parse_url(name_or_url)
  File "/home/airflow/.local/lib/python3.7/site-packages/sqlalchemy/engine/url.py", line 794, in _parse_url
    components["port"] = int(components["port"])
ValueError: invalid literal for int() with base 10: 'None'
[2023-07-19T14:59:41.458+0000] {taskinstance.py:1350} INFO - Marking task as UP_FOR_RETRY. dag_id=etl, task_id=extract_postgresql_data, execution_date=20230719T145938, start_date=20230719T145941, end_date=20230719T145941
[2023-07-19T14:59:41.474+0000] {standard_task_runner.py:109} ERROR - Failed to execute job 8 for task extract_postgresql_data (invalid literal for int() with base 10: 'None'; 134)
[2023-07-19T14:59:41.520+0000] {local_task_job_runner.py:225} INFO - Task exited with return code 1
[2023-07-19T14:59:41.587+0000] {taskinstance.py:2653} INFO - 0 downstream tasks scheduled from follow-on schedule check
